<?xml version="1.0" ?>
<sdf version="1.10">
    <model name='paquito' canonical_link='chassis'>
        <!--Gives error, fortunately world is default-->	
        <!--<pose relative_to='world'>0 0 0 0 0 0</pose>-->
        <link name='chassis'>
	    <!-- X Y Z R P Y -->
            <pose relative_to='__model__'>0.0775 0 0.06 0 0 0</pose>
            <inertial> <!--inertial properties of the link mass, inertia matix-->
                <!--https://amesweb.info/inertia/mass-moment-of-inertia-calculator.aspx-->
                <mass>0.1</mass>
                <inertia>
                    <ixx>0.00005</ixx>
                    <ixy>0</ixy>
                    <ixz>0</ixz>
                    <iyy>0.00003</iyy>
                    <iyz>0</iyz>
                    <izz>0.00008</izz>
                </inertia>
            </inertial>
            <visual name='visual'>
                <geometry>
                    <box>
                        <size>0.2 0.155 0.003</size>
                    </box>
                </geometry>
                <!--let's add color to our link-->
                <material>
                    <ambient>0.0 0.0 0.0 1</ambient>
                    <diffuse>0.0 0.0 0.0 1</diffuse>
                    <specular>0.0 0.0 0.0 1</specular>
                </material>
            </visual>
            <collision name='collision'>
                <geometry>
                    <box>
                        <size>0.2 0.115 0.003</size>
                    </box>
                </geometry>
            </collision>
        </link>

        <link name='camera_link'>
            <pose relative_to='chassis'>0 0 0.06 0 0 0</pose>
            <visual name='visual'>
                <geometry>
                    <box>
                    <size>0.01 0.02 0.02</size>
                    </box>
                </geometry>
            </visual>
            <sensor name='my_camera' type='camera'>
                <always_on>true</always_on>
                <visualize>true</visualize>
                <update_rate>30</update_rate>
                <topic>/camera/image_raw</topic>
                <!--<gz_frame_id>camera_rgb_frame</gz_frame_id> https://robotics.stackexchange.com/questions/115141/how-to-use-a-camera-plugin-in-gazebo-sim -->
                <camera name="arducam">
                    <horizontal_fov>1.047</horizontal_fov>
                    <lens>
                        <intrinsics>
                        <!-- fx = fy = width / ( 2 * tan (hfov / 2 ) ) -->
                        <fx>329.9</fx>
                        <fy>329.9</fy>
                        <!-- cx = ( width - 1 ) / 2 -->
                        <cx>359.5</cx>
                        <!-- cy = ( height - 1 ) / 2 -->
                        <cy>539.5</cy>
                        <s>0</s>
                        </intrinsics>
                    </lens>
                    <distortion>
                        <k1>0.0</k1>
                        <k2>0.0</k2>
                        <k3>0.0</k3>
                        <p1>0.0</p1>
                        <p2>0.0</p2>
                        <center>0.5 0.5</center>
                    </distortion>
                    <image>
                        <width>1920</width>
                        <height>1080</height>
                        <!--<format>R8G8B8</format>-->
                    </image>
                    <clip>
                        <near>0.1</near>
                        <far>100</far>
                    </clip>
                </camera>
            </sensor>
        </link>

        <joint name="camera_joint" type="fixed">
            <parent>chassis</parent>
            <child>camera_link</child>
            <pose relative_to="chassis">0 0 0 0 0 0</pose>
        </joint>

	<include>
		<uri>model://paquito/wheel.sdf</uri>
		<name>front_left_wheel</name>

		<pose relative_to="chassis">0.0775 -0.1 -0.03 -1.5707 0 0</pose>
	</include>
	
	<include>
		<uri>model://paquito/wheel.sdf</uri>
		<name>rear_left_wheel</name>

		<pose relative_to="chassis">-0.0775 -0.1 -0.03 -1.5707 0 0</pose>
	</include>
	
	<include>
		<uri>model://paquito/wheel.sdf</uri>
		<name>front_right_wheel</name>

		<pose relative_to="chassis">0.0775 0.1 -0.03 1.5707 0 0</pose>
	</include>
	<include>
		<uri>model://paquito/wheel.sdf</uri>
		<name>rear_right_wheel</name>

		<pose relative_to="chassis">-0.0775 0.1 -0.03 1.5707 0 0</pose>
	</include>

        <joint name='front_left_wheel_joint' type='revolute'>
            <pose relative_to='front_left_wheel'/>
            <parent>chassis</parent>
            <child>front_left_wheel</child>
            <axis>
                <!--can be defined as any frame or even arbitrary frames-->
                    <xyz expressed_in='__model__'>0 1 0</xyz>
                    <limit>
                    <lower>-1.79769e+308</lower>    <!--negative infinity-->
                    <upper>1.79769e+308</upper>     <!--positive infinity-->
                </limit>
            </axis>
        </joint>

        <joint name='rear_left_wheel_joint' type='revolute'>
                <pose relative_to='rear_left_wheel'/>
                <parent>chassis</parent>
                <child>rear_left_wheel</child>
                <axis>
                        <!--can be defined as any frame or even arbitrary frames-->
                        <xyz expressed_in='__model__'>0 1 0</xyz>
                        <limit>
                                <lower>-1.79769e+308</lower>    <!--negative infinity-->
                                <upper>1.79769e+308</upper>     <!--positive infinity-->
                        </limit>
                </axis>
        </joint>

        <joint name='front_right_wheel_joint' type='revolute'>
                <pose relative_to='front_right_wheel'/>
                <parent>chassis</parent>
                <child>front_right_wheel</child>
                <axis>
                        <!--can be defined as any frame or even arbitrary frames-->
                        <xyz expressed_in='__model__'>0 1 0</xyz>
                        <limit>
                                <lower>-1.79769e+308</lower>    <!--negative infinity-->
                                <upper>1.79769e+308</upper>     <!--positive infinity-->
                        </limit>
                </axis>
        </joint>

        <joint name='rear_right_wheel_joint' type='revolute'>
                <pose relative_to='rear_right_wheel'/>
                <parent>chassis</parent>
                <child>rear_right_wheel</child>
                <axis>
                        <!--can be defined as any frame or even arbitrary frames-->
                        <xyz expressed_in='__model__'>0 1 0</xyz>
                        <limit>
                                <lower>-1.79769e+308</lower>    <!--negative infinity-->
                                <upper>1.79769e+308</upper>     <!--positive infinity-->
                        </limit>
                </axis>
        </joint>

    </model>
</sdf>
